Workbook

Sheet Painel
A2: Controle jurídico
A3: Escolha uma opção abaixo ou use os filtros em amarelo para acompanhar a carteira.
A4: =IFERROR(HYPERLINK("#'Painel'!A1","Painel"),"Painel") -> Painel | D4: =IFERROR(HYPERLINK("#'Ficha'!C6","Ficha do processo"),"Ficha do processo") -> Ficha do processo | G4: =IFERROR(HYPERLINK("#'Central IA'!C6","Central IA"),"Central IA") -> Central IA | J4: =IFERROR(HYPERLINK("#'Críticos'!A1","Críticos"),"Críticos") -> Críticos | M4: =IFERROR(HYPERLINK("#'Escritórios'!A1","Escritórios"),"Escritórios") -> Escritórios | P4: =IFERROR(HYPERLINK("#'Configurar'!A1","Configurar"),"Configurar") -> Configurar
A5: =IFERROR(HYPERLINK("#'Processos'!A9","Cadastrar ou editar"),"Cadastrar ou editar") -> Cadastrar ou editar | G5: =IFERROR(HYPERLINK("#'Valores'!A9","Informar valores"),"Informar valores") -> Informar valores | M5: =IFERROR(HYPERLINK("#'Andamentos'!A9","Consultar histórico"),"Consultar histórico") -> Consultar histórico
A6: ESCRITÓRIO | C6: Todos | J6: EMPRESA | L6: Todas
A8: CONSÓRCIO | C8: Todos | J8: TEMA | L8: Todos
A10: BUSCA | N10: Digite o número ou o nome de uma parte.
A12: =A15&" registros / "&SUM(Processos!$BC$10:$BC$509)&" números principais no filtro. Use a Ficha para consultar." -> 148 registros / 138 números principais no filtro. Use a Ficha para consultar.
A14: REGISTROS | K14: CRÍTICOS
A15: =COUNTIFS(Processos!$X$10:$X$509,1) -> 148 | K15: =COUNTIFS(Processos!$X$10:$X$509,1,Processos!$Y$10:$Y$509,1) -> 7
A17: linhas de acompanhamento no filtro | K17: prioridade ou restrição vigente
A19: ="Cobrar atualização: "&COUNTIFS(Processos!$X$10:$X$509,1,Processos!$AD$10:$AD$509,1)&" processos" -> Cobrar atualização: 87 processos
A20: ="Ativos: "&COUNTIFS(Processos!$X$10:$X$509,1,Processos!$C$10:$C$509,"Ativo")&" Suspensos: "&COUNTIFS(Processos!$X$10:$X$509,1,Processos!$C$10:$C$509,"Suspenso") -> Ativos: 74 Suspensos: 17 | K20: ="Encerrados: "&COUNTIFS(Processos!$X$10:$X$509,1,Processos!$C$10:$C$509,"Encerrado")&" Arquivados: "&COUNTIFS(Processos!$X$10:$X$509,1,Processos!$C$10:$C$509,"Arquivado") -> Encerrados: 15 Arquivados: 40
A22: ="Conferir preenchimento (carteira inteira): "&SUMPRODUCT(--(Processos!$AI$10:$AI$509<>""))&" cadastros, "&SUMPRODUCT(--(Valores!$N$10:$N$509<>""))&" valores e "&SUMPRODUCT(--(Andamentos!$I$10:$I$2009<>""))&" andamentos." -> Conferir preenchimento (carteira inteira): 148 cadastros, 119 valores e 55 andamentos.
A23: =IFERROR(HYPERLINK("#'Processos'!AI9","REVISAR CADASTROS"),"REVISAR CADASTROS") -> REVISAR CADASTROS | K23: =IFERROR(HYPERLINK("#'Valores'!N9","REVISAR VALORES"),"REVISAR VALORES") -> REVISAR VALORES | P23: =IFERROR(HYPERLINK("#'Andamentos'!I9","REVISAR HISTÓRICO"),"REVISAR HISTÓRICO") -> REVISAR HISTÓRICO
A24: VALORES INFORMADOS | K24: PROCESSOS POR TEMA
A26: Depósitos judiciais | F26: =IF(COUNTIFS(Valores!$M$10:$M$509,1,Valores!$D$10:$D$509,">0")+COUNTIFS(Valores!$M$10:$M$509,1,Valores!$D$10:$D$509,"=0",Valores!$D$10:$D$509,"<>")=0,"Não informado",SUMIFS(Valores!$D$10:$D$509,Valores!$M$10:$M$509,1)) -> 137749.46
A27: Bloqueios em dinheiro (saldo) | F27: =IF(COUNTIFS(Valores!$M$10:$M$509,1,Valores!$E$10:$E$509,">0")+COUNTIFS(Valores!$M$10:$M$509,1,Valores!$E$10:$E$509,"=0",Valores!$E$10:$E$509,"<>")=0,"Não informado",SUMIFS(Valores!$E$10:$E$509,Valores!$M$10:$M$509,1)) -> Não informado
A28: Benefício econômico estimado | F28: =IF(COUNTIFS(Valores!$M$10:$M$509,1,Valores!$G$10:$G$509,">0")+COUNTIFS(Valores!$M$10:$M$509,1,Valores!$G$10:$G$509,"=0",Valores!$G$10:$G$509,"<>")=0,"Não informado",SUMIFS(Valores!$G$10:$G$509,Valores!$M$10:$M$509,1)) -> Não informado
A32: Totais parciais: registros com número repetido ficam fora até a revisão na coluna T de Valores. Sem rateio de consórcio.
A45: =IFERROR(HYPERLINK("#'Processos'!A"&Configurar!$U$13,"CADASTRAR PROCESSO"),"CADASTRAR PROCESSO") -> CADASTRAR PROCESSO | M45: =IFERROR(HYPERLINK("#'Andamentos'!A9","REGISTRAR ANDAMENTO"),"REGISTRAR ANDAMENTO") -> REGISTRAR ANDAMENTO
A48: EMPRESAS | K48: CONSÓRCIOS
A50: =IF(OR(Configurar!B10="",COUNTIFS(Configurar!$B$10:B10,Configurar!B10)>1),"",Configurar!B10) -> Alta Engenharia de Infraestrutura LTDA | G50: =IF(A50="","",COUNTIFS(Processos!$X$10:$X$509,1,Processos!$E$10:$E$509,A50)) -> 0 | K50: =IF(OR(Configurar!C10="",COUNTIFS(Configurar!$C$10:C10,Configurar!C10)>1),"",Configurar!C10) -> Sem consórcio | Q50: =IF(K50="","",COUNTIFS(Processos!$X$10:$X$509,1,Processos!$F$10:$F$509,K50)) -> 0
A51: =IF(OR(Configurar!B11="",COUNTIFS(Configurar!$B$10:B11,Configurar!B11)>1),"",Configurar!B11) -> Cava Engenharia de Infraestrutura LTDA | G51: =IF(A51="","",COUNTIFS(Processos!$X$10:$X$509,1,Processos!$E$10:$E$509,A51)) -> 0 | K51: =IF(OR(Configurar!C11="",COUNTIFS(Configurar!$C$10:C11,Configurar!C11)>1),"",Configurar!C11) -> Consórcio Trail-Spavias-Alta | Q51: =IF(K51="","",COUNTIFS(Processos!$X$10:$X$509,1,Processos!$F$10:$F$509,K51)) -> 14
A52: =IF(OR(Configurar!B12="",COUNTIFS(Configurar!$B$10:B12,Configurar!B12)>1),"",Configurar!B12) -> Planep | G52: =IF(A52="","",COUNTIFS(Processos!$X$10:$X$509,1,Processos!$E$10:$E$509,A52)) -> 0 | K52: =IF(OR(Configurar!C12="",COUNTIFS(Configurar!$C$10:C12,Configurar!C12)>1),"",Configurar!C12) -> Consórcio Integral Spavias Trail Alta | Q52: =IF(K52="","",COUNTIFS(Processos!$X$10:$X$509,1,Processos!$F$10:$F$509,K52)) -> 48
A53: =IF(OR(Configurar!B13="",COUNTIFS(Configurar!$B$10:B13,Configurar!B13)>1),"",Configurar!B13) -> Strata Engenharia | G53: =IF(A53="","",COUNTIFS(Processos!$X$10:$X$509,1,Processos!$E$10:$E$509,A53)) -> 0 | K53: =IF(OR(Configurar!C13="",COUNTIFS(Configurar!$C$10:C13,Configurar!C13)>1),"",Configurar!C13) -> Consórcio Spavias Cava | Q53: =IF(K53="","",COUNTIFS(Processos!$X$10:$X$509,1,Processos!$F$10:$F$509,K53)) -> 7
A54: =IF(OR(Configurar!B14="",COUNTIFS(Configurar!$B$10:B14,Configurar!B14)>1),"",Configurar!B14) -> Alltech | G54: =IF(A54="","",COUNTIFS(Processos!$X$10:$X$509,1,Processos!$E$10:$E$509,A54)) -> 0 | K54: =IF(OR(Configurar!C14="",COUNTIFS(Configurar!$C$10:C14,Configurar!C14)>1),"",Configurar!C14) -> Consórcio Spavias Serne Spavias Trail Alta | Q54: =IF(K54="","",COUNTIFS(Processos!$X$10:$X$509,1,Processos!$F$10:$F$509,K54)) -> 2
A55: =IF(OR(Configurar!B15="",COUNTIFS(Configurar!$B$10:B15,Configurar!B15)>1),"",Configurar!B15) -> Altabio Eucalipto | G55: =IF(A55="","",COUNTIFS(Processos!$X$10:$X$509,1,Processos!$E$10:$E$509,A55)) -> 0 | K55: =IF(OR(Configurar!C15="",COUNTIFS(Configurar!$C$10:C15,Configurar!C15)>1),"",Configurar!C15) -> Consórcio Loctec Pavienge Cava Alta Setorsul | Q55: =IF(K55="","",COUNTIFS(Processos!$X$10:$X$509,1,Processos!$F$10:$F$509,K55)) -> 10
A56: =IF(OR(Configurar!B16="",COUNTIFS(Configurar!$B$10:B16,Configurar!B16)>1),"",Configurar!B16) -> Altabio Pecuária | G56: =IF(A56="","",COUNTIFS(Processos!$X$10:$X$509,1,Processos!$E$10:$E$509,A56)) -> 0 | K56: =IF(OR(Configurar!C16="",COUNTIFS(Configurar!$C$10:C16,Configurar!C16)>1),"",Configurar!C16) -> Consórcio Spavias Alta | Q56: =IF(K56="","",COUNTIFS(Processos!$X$10:$X$509,1,Processos!$F$10:$F$509,K56)) -> 7
A57: =IF(OR(Configurar!B17="",COUNTIFS(Configurar!$B$10:B17,Configurar!B17)>1),"",Configurar!B17) -> CPC - Consultoria e Participações | G57: =IF(A57="","",COUNTIFS(Processos!$X$10:$X$509,1,Processos!$E$10:$E$509,A57)) -> 0 | K57: =IF(OR(Configurar!C17="",COUNTIFS(Configurar!$C$10:C17,Configurar!C17)>1),"",Configurar!C17) -> Consórcio GA 060 | Q57: =IF(K57="","",COUNTIFS(Processos!$X$10:$X$509,1,Processos!$F$10:$F$509,K57)) -> 1
A58: =IF(OR(Configurar!B18="",COUNTIFS(Configurar!$B$10:B18,Configurar!B18)>1),"",Configurar!B18) -> Camilo de Léllis Nogueira (PF) | G58: =IF(A58="","",COUNTIFS(Processos!$X$10:$X$509,1,Processos!$E$10:$E$509,A58)) -> 0 | K58: =IF(OR(Configurar!C18="",COUNTIFS(Configurar!$C$10:C18,Configurar!C18)>1),"",Configurar!C18) -> Consórcio Alta-ECP | Q58: =IF(K58="","",COUNTIFS(Processos!$X$10:$X$509,1,Processos!$F$10:$F$509,K58)) -> 3
K59: =IF(OR(Configurar!C19="",COUNTIFS(Configurar!$C$10:C19,Configurar!C19)>1),"",Configurar!C19) -> Consórcio JEA (JM/EHL/Alta) | Q59: =IF(K59="","",COUNTIFS(Processos!$X$10:$X$509,1,Processos!$F$10:$F$509,K59)) -> 3
A60: Empresa não informada / fora da lista | G60: =COUNTIFS(Processos!$X$10:$X$509,1)-SUM(G50:G58) -> 148 | K60: Demais / sem classificação | Q60: =COUNTIFS(Processos!$X$10:$X$509,1)-SUM(Q50:Q59) -> 53

Sheet Ficha
A2: Ficha do processo
A3: Escolha o processo no campo amarelo. Use os atalhos abaixo para editar o cadastro, informar valores ou abrir o tribunal.
A4: =IFERROR(HYPERLINK("#'Painel'!A1","Painel"),"Painel") -> Painel | D4: =IFERROR(HYPERLINK("#'Ficha'!C6","Ficha do processo"),"Ficha do processo") -> Ficha do processo | G4: =IFERROR(HYPERLINK("#'Central IA'!C6","Central IA"),"Central IA") -> Central IA | J4: =IFERROR(HYPERLINK("#'Críticos'!A1","Críticos"),"Críticos") -> Críticos | M4: =IFERROR(HYPERLINK("#'Escritórios'!A1","Escritórios"),"Escritórios") -> Escritórios | P4: =IFERROR(HYPERLINK("#'Configurar'!A1","Configurar"),"Configurar") -> Configurar
A5: =IFERROR(HYPERLINK("#'Processos'!A9","Cadastrar ou editar"),"Cadastrar ou editar") -> Cadastrar ou editar | G5: =IFERROR(HYPERLINK("#'Valores'!A9","Informar valores"),"Informar valores") -> Informar valores | M5: =IFERROR(HYPERLINK("#'Andamentos'!A9","Consultar histórico"),"Consultar histórico") -> Consultar histórico
A6: PROCESSO | C6: 0016196-95.2018.5.16.0017 | N6: =IF(C6="","Selecione um processo",IF(Configurar!$U$10=0,"Número não encontrado ou duplicado",INDEX(Processos!$C$10:$C$509,Configurar!$U$10))) -> Ativo
A9: =IFERROR(HYPERLINK("#'Processos'!A"&IF(Configurar!$U$10=0,9,Configurar!$U$10+9),"EDITAR CADASTRO"),"EDITAR CADASTRO") -> EDITAR CADASTRO | H9: =IFERROR(HYPERLINK("#'Valores'!A"&IF(Configurar!$U$11=0,9,Configurar!$U$11+9),"ATUALIZAR VALORES"),"ATUALIZAR VALORES") -> ATUALIZAR VALORES | N9: =IFERROR(IF(Configurar!$U$10=0,"CONSULTAR TRIBUNAL",IF(OR(IFERROR(INDEX(Critérios!$K$10:$K$32,MATCH(INDEX(Processos!$K$10:$K$509,Configurar!$U$10),Critérios!$J$10:$J$32,0)),"")="",IFERROR(INDEX(Critérios!$K$10:$K$32,MATCH(INDEX(Processos!$K$10:$K$509,Configurar!$U$10),Critérios!$J$10:$J$32,0)),"")=0),"IDENTIFICAR ÓRGÃO",HYPERLINK(IFERROR(INDEX(Critérios!$K$10:$K$32,MATCH(INDEX(Processos!$K$10:$K$509,Configurar!$U$10),Critérios!$J$10:$J$32,0)),""),"CONSULTAR TRIBUNAL"))),"CONSULTAR TRIBUNAL") -> CONSULTAR TRIBUNAL
A11: EMPRESA | H11: CONSÓRCIO | N11: ESCRITÓRIO
A12: =IF(Configurar!$U$10=0,"",IF(INDEX(Processos!$E$10:$E$509,Configurar!$U$10)="","Não informado",INDEX(Processos!$E$10:$E$509,Configurar!$U$10))) -> Não informado | H12: =IF(Configurar!$U$10=0,"",IF(INDEX(Processos!$F$10:$F$509,Configurar!$U$10)="","Não informado",INDEX(Processos!$F$10:$F$509,Configurar!$U$10))) -> Consórcio Integral Spavias Trail Alta | N12: =IF(Configurar!$U$10=0,"",IF(INDEX(Processos!$D$10:$D$509,Configurar!$U$10)="","Não informado",INDEX(Processos!$D$10:$D$509,Configurar!$U$10))) -> BMM Advogados
A15: PARTE AUTORA | K15: PARTE RÉ
A16: =IF(LEN(IF(Configurar!$U$10=0,"",IF(INDEX(Processos!$H$10:$H$509,Configurar!$U$10)="","Não informado",INDEX(Processos!$H$10:$H$509,Configurar!$U$10))))>450,LEFT(SUBSTITUTE(SUBSTITUTE(IF(Configurar!$U$10=0,"",IF(INDEX(Processos!$H$10:$H$509,Configurar!$U$10)="","Não informado",INDEX(Processos!$H$10:$H$509,Configurar!$U$10))),CHAR(10)," "),CHAR(13)," "),450)&" [...] Consulte o cadastro completo.",SUBSTITUTE(SUBSTITUTE(IF(Configurar!$U$10=0,"",IF(INDEX(Processos!$H$10:$H$509,Configurar!$U$10)="","Não informado",INDEX(Processos!$H$10:$H$509,Configurar!$U$10))),CHAR(10)," "),CHAR(13)," ")) -> RAIMUNDO DIAS DA SILVA | K16: =IF(LEN(IF(Configurar!$U$10=0,"",IF(INDEX(Processos!$I$10:$I$509,Configurar!$U$10)="","Não informado",INDEX(Processos!$I$10:$I$509,Configurar!$U$10))))>450,LEFT(SUBSTITUTE(SUBSTITUTE(IF(Configurar!$U$10=0,"",IF(INDEX(Processos!$I$10:$I$509,Configurar!$U$10)="","Não informado",INDEX(Processos!$I$10:$I$509,Configurar!$U$10))),CHAR(10)," "),CHAR(13)," "),450)&" [...] Consulte o cadastro completo.",SUBSTITUTE(SUBSTITUTE(IF(Configurar!$U$10=0,"",IF(INDEX(Processos!$I$10:$I$509,Configurar!$U$10)="","Não informado",INDEX(Processos!$I$10:$I$509,Configurar!$U$10))),CHAR(10)," "),CHAR(13)," ")) -> CONSÓRCIO INTEGRAL SPAVIAS TRAIL ALTA
A20: TEMA / NATUREZA | H20: COMARCA / TRIBUNAL | N20: CRITICIDADE DE ORIGEM
A21: =IF(Configurar!$U$10=0,"",INDEX(Processos!$G$10:$G$509,Configurar!$U$10)&" / "&INDEX(Processos!$B$10:$B$509,Configurar!$U$10)) -> Trabalhista / Judicial | H21: =IF(Configurar!$U$10=0,"",INDEX(Processos!$J$10:$J$509,Configurar!$U$10)&" / "&INDEX(Processos!$K$10:$K$509,Configurar!$U$10)) -> VT de Estreito/MA / TRT 16ª Região (MA) | N21: =IF($C$6="","",IFERROR(IF(OR(INDEX(Origem!$AB$10:$AB$509,MATCH($C$6,Origem!$A$10:$A$509,0))="",INDEX(Origem!$AB$10:$AB$509,MATCH($C$6,Origem!$A$10:$A$509,0))="—"),"Sem classificação",INDEX(Origem!$AB$10:$AB$509,MATCH($C$6,Origem!$A$10:$A$509,0))&CHAR(10)&IF(INDEX(Origem!$AC$10:$AC$509,MATCH($C$6,Origem!$A$10:$A$509,0))="","Sem pontuação",INDEX(Origem!$AC$10:$AC$509,MATCH($C$6,Origem!$A$10:$A$509,0))&" pontos")),"Sem classificação")) -> 🔴 CRÍTICO 70 pontos
A24: FATOS E MOTIVOS
A25: =IF(LEN(IF(Configurar!$U$10=0,"",IF(INDEX(Processos!$M$10:$M$509,Configurar!$U$10)="","Não informado",INDEX(Processos!$M$10:$M$509,Configurar!$U$10))))>620,LEFT(IF(Configurar!$U$10=0,"",IF(INDEX(Processos!$M$10:$M$509,Configurar!$U$10)="","Não informado",INDEX(Processos!$M$10:$M$509,Configurar!$U$10))),620)&" [...] Consulte o texto integral na base.",IF(Configurar!$U$10=0,"",IF(INDEX(Processos!$M$10:$M$509,Configurar!$U$10)="","Não informado",INDEX(Processos!$M$10:$M$509,Configurar!$U$10)))) -> Trata-se de um processo trabalhista em que o reclamante alega ter laborado em jornada extraordinária habitual, sem o devido pagamento das horas extras.
A29: INSTAURAÇÃO | H29: PREVISÃO DE ENCERRAMENTO | N29: PRIORIDADE / RESTRIÇÕES
A30: =IF(Configurar!$U$10=0,"",IF(INDEX(Processos!$L$10:$L$509,Configurar!$U$10)="","Não informado",INDEX(Processos!$L$10:$L$509,Configurar!$U$10))) -> Não informado | H30: =IF(Configurar!$U$10=0,"",IF(INDEX(Processos!$S$10:$S$509,Configurar!$U$10)="","Não informado",INDEX(Processos!$S$10:$S$509,Configurar!$U$10))) -> Não informado | N30: =IF(Configurar!$U$10=0,"",IF(INDEX(Processos!$N$10:$N$509,Configurar!$U$10)="","Prioridade não informada",INDEX(Processos!$N$10:$N$509,Configurar!$U$10))&CHAR(10)&"Bloqueio: "&IF(INDEX(Processos!$O$10:$O$509,Configurar!$U$10)="","não informado",INDEX(Processos!$O$10:$O$509,Configurar!$U$10))&" / Penhora: "&IF(INDEX(Processos!$P$10:$P$509,Configurar!$U$10)="","não informada",INDEX(Processos!$P$10:$P$509,Configurar!$U$10))) -> Crítica Bloqueio: não informado / Penhora: não informada
A33: ANDAMENTO
A35: ÚLTIMO ANDAMENTO REGISTRADO
A36: =IF(LEN(IF(Configurar!$U$10=0,"",IF(INDEX(Processos!$AC$10:$AC$509,Configurar!$U$10)="","Não informado",INDEX(Processos!$AC$10:$AC$509,Configurar!$U$10))))>650,LEFT(IF(Configurar!$U$10=0,"",IF(INDEX(Processos!$AC$10:$AC$509,Configurar!$U$10)="","Não informado",INDEX(Processos!$AC$10:$AC$509,Configurar!$U$10))),650)&" [...] Consulte o texto integral na base.",IF(Configurar!$U$10=0,"",IF(INDEX(Processos!$AC$10:$AC$509,Configurar!$U$10)="","Não informado",INDEX(Processos!$AC$10:$AC$509,Configurar!$U$10)))) -> 07/0/2023 - Remetido os autos para TST para processar recurso. [...] histórico completo em Observações
A40: DATA DO ANDAMENTO | H40: REGISTRADO / ATUALIZADO
A41: =IF(Configurar!$U$10=0,"",IF(INDEX(Processos!$AP$10:$AP$509,Configurar!$U$10)="","Não informado",INDEX(Processos!$AP$10:$AP$509,Configurar!$U$10))) -> Não informado | H41: =IF(Configurar!$U$10=0,"",IF(INDEX(Processos!$Z$10:$Z$509,Configurar!$U$10)="","Não informado",INDEX(Processos!$Z$10:$Z$509,Configurar!$U$10))) -> 46055
A49: FINANCEIRO E AVALIAÇÃO DO ESCRITÓRIO
A51: VALOR DA CAUSA | H51: CONDENAÇÃO / EXECUÇÃO | N51: ÊXITO ESTIMADO
A52: =IF(Configurar!$U$10=0,"",IF(Configurar!$U$11=0,"Não informado",IF(INDEX(Valores!$B$10:$B$509,Configurar!$U$11)="","Não informado",INDEX(Valores!$B$10:$B$509,Configurar!$U$11)))) -> 119383.18 | H52: =IF(Configurar!$U$10=0,"",IF(Configurar!$U$11=0,"Não informado",IF(INDEX(Valores!$C$10:$C$509,Configurar!$U$11)="","Não informado",INDEX(Valores!$C$10:$C$509,Configurar!$U$11)))) -> 108062.21 | N52: =IF(Configurar!$U$10=0,"",IF(Configurar!$U$11=0,"Não informado",IF(INDEX(Valores!$H$10:$H$509,Configurar!$U$11)="","Não informado",INDEX(Valores!$H$10:$H$509,Configurar!$U$11)))) -> Não informado
A55: DEPÓSITOS JUDICIAIS | H55: BLOQUEIOS (SALDO)
A56: =IF(Configurar!$U$10=0,"",IF(Configurar!$U$11=0,"Não informado",IF(INDEX(Valores!$D$10:$D$509,Configurar!$U$11)="","Não informado",INDEX(Valores!$D$10:$D$509,Configurar!$U$11)))) -> Não informado | H56: =IF(Configurar!$U$10=0,"",IF(Configurar!$U$11=0,"Não informado",IF(INDEX(Valores!$E$10:$E$509,Configurar!$U$11)="","Não informado",INDEX(Valores!$E$10:$E$509,Configurar!$U$11)))) -> Não informado
A59: BENEFÍCIO ESTIMADO | H59: REVISADO EM | N59: COBRAR ATUALIZAÇÃO
A60: =IF(Configurar!$U$10=0,"",IF(Configurar!$U$11=0,"Não informado",IF(INDEX(Valores!$G$10:$G$509,Configurar!$U$11)="","Não informado",INDEX(Valores!$G$10:$G$509,Configurar!$U$11)))) -> Não informado | H60: =IF(Configurar!$U$10=0,"",IF(Configurar!$U$11=0,"Não informado",IF(INDEX(Valores!$J$10:$J$509,Configurar!$U$11)="","Não informado",INDEX(Valores!$J$10:$J$509,Configurar!$U$11)))) -> Não informado | N60: =IF(Configurar!$U$10=0,"",IF(INDEX(Processos!$AD$10:$AD$509,Configurar!$U$10)=1,"Sim","Não")) -> Sim
A68: OBSERVAÇÕES
A69: =IF(LEN(IF(Configurar!$U$10=0,"",IF(INDEX(Processos!$U$10:$U$509,Configurar!$U$10)="","Sem observações adicionais",INDEX(Processos!$U$10:$U$509,Configurar!$U$10))))>900,LEFT(IF(Configurar!$U$10=0,"",IF(INDEX(Processos!$U$10:$U$509,Configurar!$U$10)="","Sem observações adicionais",INDEX(Processos!$U$10:$U$509,Configurar!$U$10))),900)&" [...] Consulte o texto integral na base.",IF(Configurar!$U$10=0,"",IF(INDEX(Processos!$U$10:$U$509,Configurar!$U$10)="","Sem observações adicionais",INDEX(Processos!$U$10:$U$509,Configurar!$U$10)))) -> Origem: BMM!54 | ID BMM-050 | Situação original: Ativo | Fase: Execução | Probabilidade de perda original: Provável | Avaliação original: PROVÁVEL INCLUSÃO POR IDPJ | Contrato: RDC 6 | Última atualização informada: 2026-02-02
A73: Atualize Processos, Valores e Andamentos. Classificação e pontuação de origem são históricas; critérios detalhados na aba Critérios.
A76: =IF(Configurar!$U$10=0,"DOCUMENTOS",IF(INDEX(Processos!$T$10:$T$509,Configurar!$U$10)="","Sem link de documentos",IFERROR(HYPERLINK(INDEX(Processos!$T$10:$T$509,Configurar!$U$10),"ABRIR DOCUMENTOS"),"ABRIR DOCUMENTOS"))) -> Sem link de documentos | K76: =IFERROR(HYPERLINK("#'Andamentos'!A9","VER HISTÓRICO COMPLETO"),"VER HISTÓRICO COMPLETO") -> VER HISTÓRICO COMPLETO
A79: DETALHES FINANCEIROS E REGISTRO ORIGINAL
A81: Valor atualizado da causa | H81: =IF(Configurar!$U$11=0,"Não informado",IF(INDEX(Valores!$U$10:$U$509,Configurar!$U$11)="","Não informado",INDEX(Valores!$U$10:$U$509,Configurar!$U$11))) -> Não informado
A86: Perda classificada na origem | H86: =IF(Configurar!$U$11=0,"Não informado",IF(INDEX(Valores!$Z$10:$Z$509,Configurar!$U$11)="","Não informado",INDEX(Valores!$Z$10:$Z$509,Configurar!$U$11))) -> Provável
A87: Duração estimada | H87: =IF(Configurar!$U$11=0,"Não informado",IF(INDEX(Valores!$AA$10:$AA$509,Configurar!$U$11)="","Não informado",INDEX(Valores!$AA$10:$AA$509,Configurar!$U$11))) -> Não informado
A89: Benefício econômico descrito | H89: =IF(Configurar!$U$11=0,"Não informado",IF(INDEX(Valores!$Y$10:$Y$509,Configurar!$U$11)="","Não informado",INDEX(Valores!$Y$10:$Y$509,Configurar!$U$11))) -> Não informado
A97: Incluir nos totais financeiros? | H97: =IF(Configurar!$U$11=0,"Não informado",IF(INDEX(Valores!$T$10:$T$509,Configurar!$U$11)="","Não informado",INDEX(Valores!$T$10:$T$509,Configurar!$U$11))) -> Sim
A100: =IFERROR(IF(COUNTIFS(Origem!$A$10:$A$157,C6)=1,HYPERLINK("#'Origem'!A"&(MATCH(C6,Origem!$A$10:$A$157,0)+9),"ABRIR REGISTRO ORIGINAL COMPLETO"),"Processo cadastrado após a migração"),"ABRIR REGISTRO ORIGINAL COMPLETO") -> ABRIR REGISTRO ORIGINAL COMPLETO
A101: Classificações e datas importadas retratam a planilha recebida; não indicam uma nova consulta aos autos.

Sheet Central IA
A2: Central IA
A3: 1. Cole o texto recebido. 2. Escolha Analisar texto. 3. Confira a prévia e aplique os itens aprovados.
A4: =IFERROR(HYPERLINK("#'Painel'!A1","Painel"),"Painel") -> Painel | D4: =IFERROR(HYPERLINK("#'Ficha'!C6","Ficha do processo"),"Ficha do processo") -> Ficha do processo | G4: =IFERROR(HYPERLINK("#'Configurar'!G64","Como conectar a IA"),"Como conectar a IA") -> Como conectar a IA
A6: 2. ESCOLHA A AÇÃO | G6: Conectado
A8: PROCESSO, SE SOUBER | C8: 0010752-95.2020.5.18.0101 | G8: FONTE DO TEXTO
A10: ESCRITÓRIO PADRÃO | C10: Frois | G10: EMPRESA PADRÃO
A12: CONSÓRCIO PADRÃO | C12: Consórcio Integral Spavias Trail Alta
A14: COMO SALVAR | C14: Revisar tudo | G14: ÚLTIMA EXECUÇÃO | H14: 21/10/2026 19:42
A16: 1. COLE O TEXTO ABAIXO. Clique na área amarela, pressione F2 e cole.
A17: Processo movido via forum
A24: Cadastro salvo. O processo já está disponível para consulta e atualização.
A27: 3. CONFIRA A PRÉVIA. Marque Sim no que deseja salvar e escolha Aplicar aprovados na ação acima.
A28: Aplicar? | B28: Processo | C28: Destino | D28: Campo / operação | E28: Atual | F28: Proposto | G28: Trecho da fonte | H28: Observação | I28: ID | J28: Aplicado em

Sheet Críticos
A2: Processos críticos
A3: Ativos ou suspensos com prioridade Crítica, bloqueio ou penhora vigente. As cores indicam a classificação de origem.
A4: =IFERROR(HYPERLINK("#'Painel'!A1","Painel"),"Painel") -> Painel | D4: =IFERROR(HYPERLINK("#'Ficha'!C6","Ficha do processo"),"Ficha do processo") -> Ficha do processo | G4: =IFERROR(HYPERLINK("#'Central IA'!C6","Atualizar com IA"),"Atualizar com IA") -> Atualizar com IA
A5: As listas seguem os filtros escolhidos no Painel.
A6: =COUNTIFS(Processos!$X$10:$X$509,1,Processos!$Y$10:$Y$509,1)&" processos críticos na seleção do Painel" -> 7 processos críticos na seleção do Painel
A7: Para consultar um caso, copie o número e selecione-o na Ficha. Cada página mostra até 50 registros.
C8: Página | D8: 1 | E8: =IFERROR(HYPERLINK("#'Critérios'!A6","VER CORES E CRITÉRIOS"),"VER CORES E CRITÉRIOS") -> VER CORES E CRITÉRIOS | I8: =MAX(1,ROUNDUP(COUNTIFS(Processos!$X$10:$X$509,1,Processos!$Y$10:$Y$509,1)/50,0)) -> 1 | J8: =MAX(1,MIN(IFERROR(INT(D8),1),I8)) -> 1
A9: Processo | B9: Escritório | C9: Autor × réu | D9: Fatos e motivos | E9: Por que é crítico | F9: Valor da causa | G9: Consultar
A10: =IF((ROW()-9+($J$8-1)*50)>COUNTIFS(Processos!$X$10:$X$509,1,Processos!$Y$10:$Y$509,1),"",IF(INDEX(Processos!$A$10:$A$509,MATCH((ROW()-9+($J$8-1)*50),Processos!$AJ$10:$AJ$509,0))="","",INDEX(Processos!$A$10:$A$509,MATCH((ROW()-9+($J$8-1)*50),Processos!$AJ$10:$AJ$509,0)))) -> 0016196-95.2018.5.16.0017 | B10: =IF((ROW()-9+($J$8-1)*50)>COUNTIFS(Processos!$X$10:$X$509,1,Processos!$Y$10:$Y$509,1),"",IF(INDEX(Processos!$D$10:$D$509,MATCH((ROW()-9+($J$8-1)*50),Processos!$AJ$10:$AJ$509,0))="","",INDEX(Processos!$D$10:$D$509,MATCH((ROW()-9+($J$8-1)*50),Processos!$AJ$10:$AJ$509,0)))) -> BMM Advogados | C10: =IF(LEN(SUBSTITUTE(SUBSTITUTE(IF(LEN(IF((ROW()-9+($J$8-1)*50)>COUNTIFS(Processos!$X$10:$X$509,1,Processos!$Y$10:$Y$509,1),"",IF(INDEX(Processos!$H$10:$H$509,MATCH((ROW()-9+($J$8-1)*50),Processos!$AJ$10:$AJ$509,0))&" × "&INDEX(Processos!$I$10:$I$509,MATCH((ROW()-9+($J$8-1)*50),Processos!$AJ$10:$AJ$509,0))="","",INDEX(Processos!$H$10:$H$509,MATCH((ROW()-9+($J$8-1)*50),Processos!$AJ$10:$AJ$509,0))&" × "&INDEX(Processos!$I$10:$I$509,MATCH((ROW()-9+($J$8-1)*50),Processos!$AJ$10:$AJ$509,0)))))>190,LEFT(IF((ROW()-9+($J$8-1)*50)>COUNTIFS(Processos!$X$10:$X$509,1,Processos!$Y$10:$Y$509,1),"",IF(INDEX(Processos!$H$10:$H$509,MATCH((ROW()-9+($J$8-1)*50),Processos!$AJ$10:$AJ$509,0))&" × "&INDEX(Processos!$I$10:$I$509,MATCH((ROW()-9+($J$8-1)*50),Processos!$AJ$10:$AJ$509,0))="","",INDEX(Processos!$H$10:$H$509,MATCH((ROW()-9+($J$8-1)*50),Processos!$AJ$10:$AJ$509,0))&" × "&INDEX(Processos!$I$10:$I$509,MATCH((ROW()-9+($J$8-1)*50),Processos!$AJ$10:$AJ$509,0)))),190)&" [...]",IF((ROW()-9+($J$8-1)*50)>COUNTIFS(Processos!$X$10:$X$509,1,Processos!$Y$10:$Y$509,1),"",IF(INDEX(Processos!$H$10:$H$509,MATCH((ROW()-9+($J$8-1)*50),Processos!$AJ$10:$AJ$509,0))&" × "&INDEX(Processos!$I$10:$I$509,MATCH((ROW()-9+($J$8-1)*50),Processos!$AJ$10:$AJ$509,0))="","",INDEX(Processos!$H$10:$H$509,MATCH((ROW()-9+($J$8-1)*50),Processos!$AJ$10:$AJ$509,0))&" × "&INDEX(Processos!$I$10:$I$509,MATCH((ROW()-9+($J$8-1)*50),Processos!$AJ$10:$AJ$509,0))))),CHAR(10)," "),CHAR(13)," "))>150,LEFT(SUBSTITUTE(SUBSTITUTE(IF(LEN(IF((ROW()-9+($J$8-1)*50)>COUNTIFS(Processos!$X$10:$X$509,1,Processos!$Y$10:$Y$509,1),"",IF(INDEX(Processos!$H$10:$H$509,MATCH((ROW()-9+($J$8-1)*50),Processos!$AJ$10:$AJ$509,0))&" × "&INDEX(Processos!$I$10:$I$509,MATCH((ROW()-9+($J$8-1)*50),Processos!$AJ$10:$AJ$509,0))="","",INDEX(Processos!$H$10:$H$509,MATCH((ROW()-9+($J$8-1)*50),Processos!$AJ$10:$AJ$509,0))&" × "&INDEX(Processos!$I$10:$I$509,MATCH((ROW()-9+($J$8-1)*50),Processos!$AJ$10:$AJ$509,0)))))>190,LEFT(IF((ROW()-9+($J$8-1)*50)>COUNTIFS(Processos!$X$10:$X$509,1,Processos!$Y$10:$Y$509,1),"",IF(INDEX(Processos!$H$10:$H$509,MATCH((ROW()-9+($J$8-1)*50),Processos!$AJ$10:$AJ$509,0))&" × "&INDEX(Processos!$I$10:$I$509,MATCH((ROW()-9+($J$8-1)*50),Processos!$AJ$10:$AJ$509,0))="","",INDEX(Processos!$H$10:$H$509,MATCH((ROW()-9+($J$8-1)*50),Processos!$AJ$10:$AJ$509,0))&" × "&INDEX(Processos!$I$10:$I$509,MATCH((ROW()-9+($J$8-1)*50),Processos!$AJ$10:$AJ$509,0)))),190)&" [...]",IF((ROW()-9+($J$8-1)*50)>COUNTIFS(Processos!$X$10:$X$509,1,Processos!$Y$10:$Y$509,1),"",IF(INDEX(Processos!$H$10:$H$509,MATCH((ROW()-9+($J$8-1)*50),Processos!$AJ$10:$AJ$509,0))&" × "&INDEX(Processos!$I$10:$I$509,MATCH((ROW()-9+($J$8-1)*50),Processos!$AJ$10:$AJ$509,0))="","",INDEX(Processos!$H$10:$H$509,MATCH((ROW()-9+($J$8-1)*50),Processos!$AJ$10:$AJ$509,0))&" × "&INDEX(Processos!$I$10:$I$509,MATCH((ROW()-9+($J$8-1)*50),Processos!$AJ$10:$AJ$509,0))))),CHAR(10)," "),CHAR(13)," "),150)&" [...]",SUBSTITUTE(SUBSTITUTE(IF(LEN(IF((ROW()-9+($J$8-1)*50)>COUNTIFS(Processos!$X$10:$X$509,1,Processos!$Y$10:$Y$509,1),"",IF(INDEX(Processos!$H$10:$H$509,MATCH((ROW()-9+($J$8-1)*50),Processos!$AJ$10:$AJ$509,0))&" × "&INDEX(Processos!$I$10:$I$509,MATCH((ROW()-9+($J$8-1)*50),Processos!$AJ$10:$AJ$509,0))="","",INDEX(Processos!$H$10:$H$509,MATCH((ROW()-9+($J$8-1)*50),Processos!$AJ$10:$AJ$509,0))&" × "&INDEX(Processos!$I$10:$I$509,MATCH((ROW()-9+($J$8-1)*50),Processos!$AJ$10:$AJ$509,0)))))>190,LEFT(IF((ROW()-9+($J$8-1)*50)>COUNTIFS(Processos!$X$10:$X$509,1,Processos!$Y$10:$Y$509,1),"",IF(INDEX(Processos!$H$10:$H$509,MATCH((ROW()-9+($J$8-1)*50),Processos!$AJ$10:$AJ$509,0))&" × "&INDEX(Processos!$I$10:$I$509,MATCH((ROW()-9+($J$8-1)*50),Processos!$AJ$10:$AJ$509,0))="","",INDEX(Processos!$H$10:$H$509,MATCH((ROW()-9+($J$8-1)*50),Processos!$AJ$10:$AJ$509,0))&" × "&INDEX(Processos!$I$10:$I$509,MATCH((ROW()-9+($J$8-1)*50),Processos!$AJ$10:$AJ$509,0)))),190)&" [...]",IF((ROW()-9+($J$8-1)*50)>COUNTIFS(Processos!$X$10:$X$509,1,Processos!$Y$10:$Y$509,1),"",IF(INDEX(Processos!$H$10:$H$509,MATCH((ROW()-9+($J$8-1)*50),Processos!$AJ$10:$AJ$509,0))&" × "&INDEX(Processos!$I$10:$I$509,MATCH((ROW()-9+($J$8-1)*50),Processos!$AJ$10:$AJ$509,0))="","",INDEX(Processos!$H$10:$H$509,MATCH((ROW()-9+($J$8-1)*50),Processos!$AJ$10:$AJ$509,0))&" × "&INDEX(Processos!$I$10:$I$509,MATCH((ROW()-9+($J$8-1)*50),Processos!$AJ$10:$AJ$509,0))))),CHAR(10)," "),CHAR(13)," ")) -> RAIMUNDO DIAS DA SILVA × CONSÓRCIO INTEGRAL SPAVIAS TRAIL ALTA | D10: =SUBSTITUTE(SUBSTITUTE(IF(LEN(IF((ROW()-9+($J$8-1)*50)>COUNTIFS(Processos!$X$10:$X$509,1,Processos!$Y$10:$Y$509,1),"",IF(INDEX(Processos!$M$10:$M$509,MATCH((ROW()-9+($J$8-1)*50),Processos!$AJ$10:$AJ$509,0))="","",INDEX(Processos!$M$10:$M$509,MATCH((ROW()-9+($J$8-1)*50),Processos!$AJ$10:$AJ$509,0)))))>190,LEFT(IF((ROW()-9+($J$8-1)*50)>COUNTIFS(Processos!$X$10:$X$509,1,Processos!$Y$10:$Y$509,1),"",IF(INDEX(Processos!$M$10:$M$509,MATCH((ROW()-9+($J$8-1)*50),Processos!$AJ$10:$AJ$509,0))="","",INDEX(Processos!$M$10:$M$509,MATCH((ROW()-9+($J$8-1)*50),Processos!$AJ$10:$AJ$509,0)))),190)&" [...]",IF((ROW()-9+($J$8-1)*50)>COUNTIFS(Processos!$X$10:$X$509,1,Processos!$Y$10:$Y$509,1),"",IF(INDEX(Processos!$M$10:$M$509,MATCH((ROW()-9+($J$8-1)*50),Processos!$AJ$10:$AJ$509,0))="","",INDEX(Processos!$M$10:$M$509,MATCH((ROW()-9+($J$8-1)*50),Processos!$AJ$10:$AJ$509,0))))),CHAR(10)," "),CHAR(13)," ") -> Trata-se de um processo trabalhista em que o reclamante alega ter laborado em jornada extraordinária habitual, sem o devido pagamento das horas extras. | E10: =IF($A10="","",IFERROR(INDEX(Processos!$AR$10:$AR$509,MATCH($A10,Processos!$A$10:$A$509,0)),"")&CHAR(10)&IFERROR(IF(OR(INDEX(Origem!$AB$10:$AB$509,MATCH($A10,Origem!$A$10:$A$509,0))="",INDEX(Origem!$AB$10:$AB$509,MATCH($A10,Origem!$A$10:$A$509,0))="—"),"Origem: sem classificação","Origem: "&INDEX(Origem!$AB$10:$AB$509,MATCH($A10,Origem!$A$10:$A$509,0))&IF(INDEX(Origem!$AC$10:$AC$509,MATCH($A10,Origem!$A$10:$A$509,0))=""," (sem pontuação)"," • "&INDEX(Origem!$AC$10:$AC$509,MATCH($A10,Origem!$A$10:$A$509,0))&" pontos")),"Origem: sem classificação")) -> Prioridade crítica. Criticidade herdada da planilha de origem; validar. Não confirma bloqueio/penhora vigente. Origem: 🔴 CRÍTICO • 70 pontos | F10: =IF((ROW()-9+($J$8-1)*50)>COUNTIFS(Processos!$X$10:$X$509,1,Processos!$Y$10:$Y$509,1),"",IF(INDEX(Processos!$AQ$10:$AQ$509,MATCH((ROW()-9+($J$8-1)*50),Processos!$AJ$10:$AJ$509,0))="","",INDEX(Processos!$AQ$10:$AQ$509,MATCH((ROW()-9+($J$8-1)*50),Processos!$AJ$10:$AJ$509,0)))) -> 119383.18 | G10: =IF((ROW()-9+($J$8-1)*50)>COUNTIFS(Processos!$X$10:$X$509,1,Processos!$Y$10:$Y$509,1),"",IFERROR(HYPERLINK("#'Ficha'!C6","Selecionar na Ficha"),"Selecionar na Ficha")) -> Selecionar na Ficha
A11: =IF((ROW()-9+($J$8-1)*50)>COUNTIFS(Processos!$X$10:$X$509,1,Processos!$Y$10:$Y$509,1),"",IF(INDEX(Processos!$A$10:$A$509,MATCH((ROW()-9+($J$8-1)*50),Processos!$AJ$10:$AJ$509,0))="","",INDEX(Processos!$A$10:$A$509,MATCH((ROW()-9+($J$8-1)*50),Processos!$AJ$10:$AJ$509,0)))) -> 0010552-28.2019.5.03.0138 | B11: =IF((ROW()-9+($J$8-1)*50)>COUNTIFS(Processos!$X$10:$X$509,1,Processos!$Y$10:$Y$509,1),"",IF(INDEX(Processos!$D$10:$D$509,MATCH((ROW()-9+($J$8-1)*50),Processos!$AJ$10:$AJ$509,0))="","",INDEX(Processos!$D$10:$D$509,MATCH((ROW()-9+($J$8-1)*50),Processos!$AJ$10:$AJ$509,0)))) -> BMM Advogados | C11: =IF(LEN(SUBSTITUTE(SUBSTITUTE(IF(LEN(IF((ROW()-9+($J$8-1)*50)>COUNTIFS(Processos!$X$10:$X$509,1,Processos!$Y$10:$Y$509,1),"",IF(INDEX(Processos!$H$10:$H$509,MATCH((ROW()-9+($J$8-1)*50),Processos!$AJ$10:$AJ$509,0))&" × "&INDEX(Processos!$I$10:$I$509,MATCH((ROW()-9+($J$8-1)*50),Processos!$AJ$10:$AJ$509,0))="","",INDEX(Processos!$H$10:$H$509,MATCH((ROW()-9+($J$8-1)*50),Processos!$AJ$10:$AJ$509,0))&" × "&INDEX(Processos!$I$10:$I$509,MATCH((ROW()-9+($J$8-1)*50),Processos!$AJ$10:$AJ$509,0)))))>190,LEFT(IF((ROW()-9+($J$8-1)*50)>COUNTIFS(Processos!$X$10:$X$509,1,Processos!$Y$10:$Y$509,1),"",IF(INDEX(Processos!$H$10:$H$509,MATCH((ROW()-9+($J$8-1)*50),Processos!$AJ$10:$AJ$509,0))&" × "&INDEX(Processos!$I$10:$I$509,MATCH((ROW()-9+($J$8-1)*50),Processos!$AJ$10:$AJ$509,0))="","",INDEX(Processos!$H$10:$H$509,MATCH((ROW()-9+($J$8-1)*50),Processos!$AJ$10:$AJ$509,0))&" × "&INDEX(Processos!$I$10:$I$509,MATCH((ROW()-9+($J$8-1)*50),Processos!$AJ$10:$AJ$509,0)))),190)&" [...]",IF((ROW()-9+($J$8-1)*50)>COUNTIFS(Processos!$X$10:$X$509,1,Processos!$Y$10:$Y$509,1),"",IF(INDEX(Processos!$H$10:$H$509,MATCH((ROW()-9+($J$8-1)*50),Processos!$AJ$10:$AJ$509,0))&" × "&INDEX(Processos!$I$10:$I$509,MATCH((ROW()-9+($J$8-1)*50),Processos!$AJ$10:$AJ$509,0))="","",INDEX(Processos!$H$10:$H$509,MATCH((ROW()-9+($J$8-1)*50),Processos!$AJ$10:$AJ$509,0))&" × "&INDEX(Processos!$I$10:$I$509,MATCH((ROW()-9+($J$8-1)*50),Processos!$AJ$10:$AJ$509,0))))),CHAR(10)," "),CHAR(13)," "))>150,LEFT(SUBSTITUTE(SUBSTITUTE(IF(LEN(IF((ROW()-9+($J$8-1)*50)>COUNTIFS(Processos!$X$10:$X$509,1,Processos!$Y$10:$Y$509,1),"",IF(INDEX(Processos!$H$10:$H$509,MATCH((ROW()-9+($J$8-1)*50),Processos!$AJ$10:$AJ$509,0))&" × "&INDEX(Processos!$I$10:$I$509,MATCH((ROW()-9+($J$8-1)*50),Processos!$AJ$10:$AJ$509,0))="","",INDEX(Processos!$H$10:$H$509,MATCH((ROW()-9+($J$8-1)*50),Processos!$AJ$10:$AJ$509,0))&" × "&INDEX(Processos!$I$10:$I$509,MATCH((ROW()-9+($J$8-1)*50),Processos!$AJ$10:$AJ$509,0)))))>190,LEFT(IF((ROW()-9+($J$8-1)*50)>COUNTIFS(Processos!$X$10:$X$509,1,Processos!$Y$10:$Y$509,1),"",IF(INDEX(Processos!$H$10:$H$509,MATCH((ROW()-9+($J$8-1)*50),Processos!$AJ$10:$AJ$509,0))&" × "&INDEX(Processos!$I$10:$I$509,MATCH((ROW()-9+($J$8-1)*50),Processos!$AJ$10:$AJ$509,0))="","",INDEX(Processos!$H$10:$H$509,MATCH((ROW()-9+($J$8-1)*50),Processos!$AJ$10:$AJ$509,0))&" × "&INDEX(Processos!$I$10:$I$509,MATCH((ROW()-9+($J$8-1)*50),Processos!$AJ$10:$AJ$509,0)))),190)&" [...]",IF((ROW()-9+($J$8-1)*50)>COUNTIFS(Processos!$X$10:$X$509,1,Processos!$Y$10:$Y$509,1),"",IF(INDEX(Processos!$H$10:$H$509,MATCH((ROW()-9+($J$8-1)*50),Processos!$AJ$10:$AJ$509,0))&" × "&INDEX(Processos!$I$10:$I$509,MATCH((ROW()-9+($J$8-1)*50),Processos!$AJ$10:$AJ$509,0))="","",INDEX(Processos!$H$10:$H$509,MATCH((ROW()-9+($J$8-1)*50),Processos!$AJ$10:$AJ$509,0))&" × "&INDEX(Processos!$I$10:$I$509,MATCH((ROW()-9+($J$8-1)*50),Processos!$AJ$10:$AJ$509,0))))),CHAR(10)," "),CHAR(13)," "),150)&" [...]",SUBSTITUTE(SUBSTITUTE(IF(LEN(IF((ROW()-9+($J$8-1)*50)>COUNTIFS(Processos!$X$10:$X$509,1,Processos!$Y$10:$Y$509,1),"",IF(INDEX(Processos!$H$10:$H$509,MATCH((ROW()-9+($J$8-1)*50),Processos!$AJ$10:$AJ$509,0))&" × "&INDEX(Processos!$I$10:$I$509,MATCH((ROW()-9+($J$8-1)*50),Processos!$AJ$10:$AJ$509,0))="","",INDEX(Processos!$H$10:$H$509,MATCH((ROW()-9+($J$8-1)*50),Processos!$AJ$10:$AJ$509,0))&" × "&INDEX(Processos!$I$10:$I$509,MATCH((ROW()-9+($J$8-1)*50),Processos!$AJ$10:$AJ$509,0)))))>190,LEFT(IF((ROW()-9+($J$8-1)*50)>COUNTIFS(Processos!$X$10:$X$509,1,Processos!$Y$10:$Y$509,1),"",IF(INDEX(Processos!$H$10:$H$509,MATCH((ROW()-9+($J$8-1)*50),Processos!$AJ$10:$AJ$509,0))&" × "&INDEX(Processos!$I$10:$I$509,MATCH((ROW()-9+($J$8-1)*50),Processos!$AJ$10:$AJ$509,0))="","",INDEX(Processos!$H$10:$H$509,MATCH((ROW()-9+($J$8-1)*50),Processos!$AJ$10:$AJ$509,0))&" × "&INDEX(Processos!$I$10:$I$509,MATCH((ROW()-9+($J$8-1)*50),Processos!$AJ$10:$AJ$509,0)))),190)&" [...]",IF((ROW()-9+($J$8-1)*50)>COUNTIFS(Processos!$X$10:$X$509,1,Processos!$Y$10:$Y$509,1),"",IF(INDEX(Processos!$H$10:$H$509,MATCH((ROW()-9+($J$8-1)*50),Processos!$AJ$10:$AJ$509,0))&" × "&INDEX(Processos!$I$10:$I$509,MATCH((ROW()-9+($J$8-1)*50),Processos!$AJ$10:$AJ$509,0))="","",INDEX(Processos!$H$10:$H$509,MATCH((ROW()-9+($J$8-1)*50),Processos!$AJ$10:$AJ$509,0))&" × "&INDEX(Processos!$I$10:$I$509,MATCH((ROW()-9+($J$8-1)*50),Processos!$AJ$10:$AJ$509,0))))),CHAR(10)," "),CHAR(13)," ")) -> GUILHERME SANTOS MOREIRA × 1 - Consórcio Spavias - Alta 2 - Spavias Engenharia LTDA 3 - Alta Engenharia 4 - Cava Engenharia | D11: =SUBSTITUTE(SUBSTITUTE(IF(LEN(IF((ROW()-9+($J$8-1)*50)>COUNTIFS(Processos!$X$10:$X$509,1,Processos!$Y$10:$Y$509,1),"",IF(INDEX(Processos!$M$10:$M$509,MATCH((ROW()-9+($J$8-1)*50),Processos!$AJ$10:$AJ$509,0))="","",INDEX(Processos!$M$10:$M$509,MATCH((ROW()-9+($J$8-1)*50),Processos!$AJ$10:$AJ$509,0)))))>190,LEFT(IF((ROW()-9+($J$8-1)*50)>COUNTIFS(Processos!$X$10:$X$509,1,Processos!$Y$10:$Y$509,1),"",IF(INDEX(Processos!$M$10:$M$509,MATCH((ROW()-9+($J$8-1)*50),Processos!$AJ$10:$AJ$509,0))="","",INDEX(Processos!$M$10:$M$509,MATCH((ROW()-9+($J$8-1)*50),Processos!$AJ$10:$AJ$509,0)))),190)&" [...]",IF((ROW()-9+($J$8-1)*50)>COUNTIFS(Processos!$X$10:$X$509,1,Processos!$Y$10:$Y$509,1),"",IF(INDEX(Processos!$M$10:$M$509,MATCH((ROW()-9+($J$8-1)*50),Processos!$AJ$10:$AJ$509,0))="","",INDEX(Processos!$M$10:$M$509,MATCH((ROW()-9+($J$8-1)*50),Processos!$AJ$10:$AJ$509,0))))),CHAR(10)," "),CHAR(13)," ") -> O trabalhador ajuizou ação contra o Consórcio Spavias Cava alegando que trabalhou de 2015 a 2019 como encarregado de departamento pessoal, com salário de R$ 4.076,43. Afirma que não recebeu [...] | E11: =IF($A11="","",IFERROR(INDEX(Processos!$AR$10:$AR$509,MATCH($A11,Processos!$A$10:$A$509,0)),"")&CHAR(10)&IFERROR(IF(OR(INDEX(Origem!$AB$10:$AB$509,MATCH($A11,Origem!$A$10:$A$509,0))="",INDEX(Origem!$AB$10:$AB$509,MATCH($A11,Origem!$A$10:$A$509,0))="—"),"Origem: sem classificação","Origem: "&INDEX(Origem!$AB$10:$AB$509,MATCH($A11,Origem!$A$10:$A$509,0))&IF(INDEX(Origem!$AC$10:$AC$509,MATCH($A11,Origem!$A$10:$A$509,0))=""," (sem pontuação)"," • "&INDEX(Origem!$AC$10:$AC$509,MATCH($A11,Origem!$A$10:$A$509,0))&" pontos")),"Origem: sem classificação")) -> Prioridade crítica. Criticidade herdada da planilha de origem; validar. Não confirma bloqueio/penhora vigente. Origem: 🔴 CRÍTICO • 70 pontos | F11: =IF((ROW()-9+($J$8-1)*50)>COUNTIFS(Processos!$X$10:$X$509,1,Processos!$Y$10:$Y$509,1),"",IF(INDEX(Processos!$AQ$10:$AQ$509,MATCH((ROW()-9+($J$8-1)*50),Processos!$AJ$10:$AJ$509,0))="","",INDEX(Processos!$AQ$10:$AQ$509,MATCH((ROW()-9+($J$8-1)*50),Processos!$AJ$10:$AJ$509,0)))) -> 80298.47 | G11: =IF((ROW()-9+($J$8-1)*50)>COUNTIFS(Processos!$X$10:$X$509,1,Processos!$Y$10:$Y$509,1),"",IFERROR(HYPERLINK("#'Ficha'!C6","Selecionar na Ficha"),"Selecionar na Ficha")) -> Selecionar na Ficha
A12: =IF((ROW()-9+($J$8-1)*50)>COUNTIFS(Processos!$X$10:$X$509,1,Processos!$Y$10:$Y$509,1),"",IF(INDEX(Processos!$A$10:$A$509,MATCH((ROW()-9+($J$8-1)*50),Processos!$AJ$10:$AJ$509,0))="","",INDEX(Processos!$A$10:$A$509,MATCH((ROW()-9+($J$8-1)*50),Processos!$AJ$10:$AJ$509,0)))) -> 0010471-11.2021.5.03.0138 | B12: =IF((ROW()-9+($J$8-1)*50)>COUNTIFS(Processos!$X$10:$X$509,1,Processos!$Y$10:$Y$509,1),"",IF(INDEX(Processos!$D$10:$D$509,MATCH((ROW()-9+($J$8-1)*50),Processos!$AJ$10:$AJ$509,0))="","",INDEX(Processos!$D$10:$D$509,MATCH((ROW()-9+($J$8-1)*50),Processos!$AJ$10:$AJ$509,0)))) -> BMM Advogados | C12: =IF(LEN(SUBSTITUTE(SUBSTITUTE(IF(LEN(IF((ROW()-9+($J$8-1)*50)>COUNTIFS(Processos!$X$10:$X$509,1,Processos!$Y$10:$Y$509,1),"",IF(INDEX(Processos!$H$10:$H$509,MATCH((ROW()-9+($J$8-1)*50),Processos!$AJ$10:$AJ$509,0))&" × "&INDEX(Processos!$I$10:$I$509,MATCH((ROW()-9+($J$8-1)*50),Processos!$AJ$10:$AJ$509,0))="","",INDEX(Processos!$H$10:$H$509,MATCH((ROW()-9+($J$8-1)*50),Processos!$AJ$10:$AJ$509,0))&" × "&INDEX(Processos!$I$10:$I$509,MATCH((ROW()-9+($J$8-1)*50),Processos!$AJ$10:$AJ$509,0)))))>190,LEFT(IF((ROW()-9+($J$8-1)*50)>COUNTIFS(Processos!$X$10:$X$509,1,Processos!$Y$10:$Y$509,1),"",IF(INDEX(Processos!$H$10:$H$509,MATCH((ROW()-9+($J$8-1)*50),Processos!$AJ$10:$AJ$509,0))&" × "&INDEX(Processos!$I$10:$I$509,MATCH((ROW()-9+($J$8-1)*50),Processos!$AJ$10:$AJ$509,0))="","",INDEX(Processos!$H$10:$H$509,MATCH((ROW()-9+($J$8-1)*50),Processos!$AJ$10:$AJ$509,0))&" × "&INDEX(Processos!$I$10:$I$509,MATCH((ROW()-9+($J$8-1)*50),Processos!$AJ$10:$AJ$509,0)))),190)&" [...]",IF((ROW()-9+($J$8-1)*50)>COUNTIFS(Processos!$X$10:$X$509,1,Processos!$Y$10:$Y$509,1),"",IF(INDEX(Processos!$H$10:$H$509,MATCH((ROW()-9+($J$8-1)*50),Processos!$AJ$10:$AJ$509,0))&" × "&INDEX(Processos!$I$10:$I$509,MATCH((ROW()-9+($J$8-1)*50),Processos!$AJ$10:$AJ$509,0))="","",INDEX(Processos!$H$10:$H$509,MATCH((ROW()-9+($J$8-1)*50),Processos!$AJ$10:$AJ$509,0))&" × "&INDEX(Processos!$I$10:$I$509,MATCH((ROW()-9+($J$8-1)*50),Processos!$AJ$10:$AJ$509,0))))),CHAR(10)," "),CHAR(13)," "))>150,LEFT(SUBSTITUTE(SUBSTITUTE(IF(LEN(IF((ROW()-9+($J$8-1)*50)>COUNTIFS(Processos!$X$10:$X$509,1,Processos!$Y$10:$Y$509,1),"",IF(INDEX(Processos!$H$10:$H$509,MATCH((ROW()-9+($J$8-1)*50),Processos!$AJ$10:$AJ$509,0))&" × "&INDEX(Processos!$I$10:$I$509,MATCH((ROW()-9+($J$8-1)*50),Processos!$AJ$10:$AJ$509,0))="","",INDEX(Processos!$H$10:$H$509,MATCH((ROW()-9+($J$8-1)*50),Processos!$AJ$10:$AJ$509,0))&" × "&INDEX(Processos!$I$10:$I$509,MATCH((ROW()-9+($J$8-1)*50),Processos!$AJ$10:$AJ$509,0)))))>190,LEFT(IF((ROW()-9+($J$8-1)*50)>COUNTIFS(Processos!$X$10:$X$509,1,Processos!$Y$10:$Y$509,1),"",IF(INDEX(Processos!$H$10:$H$509,MATCH((ROW()-9+($J$8-1)*50),Processos!$AJ$10:$AJ$509,0))&" × "&INDEX(Processos!$I$10:$I$509,MATCH((ROW()-9+($J$8-1)*50),Processos!$AJ$10:$AJ$509,0))="","",INDEX(Processos!$H$10:$H$509,MATCH((ROW()-9+($J$8-1)*50),Processos!$AJ$10:$AJ$509,0))&" × "&INDEX(Processos!$I$10:$I$509,MATCH((ROW()-9+($J$8-1)*50),Processos!$AJ$10:$AJ$509,0)))),190)&" [...]",IF((ROW()-9+($J$8-1)*50)>COUNTIFS(Processos!$X$10:$X$509,1,Processos!$Y$10:$Y$509,1),"",IF(INDEX(Processos!$H$10:$H$509,MATCH((ROW()-9+($J$8-1)*50),Processos!$AJ$10:$AJ$509,0))&" × "&INDEX(Processos!$I$10:$I$509,MATCH((ROW()-9+($J$8-1)*50),Processos!$AJ$10:$AJ$509,0))="","",INDEX(Processos!$H$10:$H$509,MATCH((ROW()-9+($J$8-1)*50),Processos!$AJ$10:$AJ$509,0))&" × "&INDEX(Processos!$I$10:$I$509,MATCH((ROW()-9+($J$8-1)*50),Processos!$AJ$10:$AJ$509,0))))),CHAR(10)," "),CHAR(13)," "),150)&" [...]",SUBSTITUTE(SUBSTITUTE(IF(LEN(IF((ROW()-9+($J$8-1)*50)>COUNTIFS(Processos!$X$10:$X$509,1,Processos!$Y$10:$Y$509,1),"",IF(INDEX(Processos!$H$10:$H$509,MATCH((ROW()-9+($J$8-1)*50),Processos!$AJ$10:$AJ$509,0))&" × "&INDEX(Processos!$I$10:$I$509,MATCH((ROW()-9+($J$8-1)*50),Processos!$AJ$10:$AJ$509,0))="","",INDEX(Processos!$H$10:$H$509,MATCH((ROW()-9+($J$8-1)*50),Processos!$AJ$10:$AJ$509,0))&" × "&INDEX(Processos!$I$10:$I$509,MATCH((ROW()-9+($J$8-1)*50),Processos!$AJ$10:$AJ$509,0)))))>190,LEFT(IF((ROW()-9+($J$8-1)*50)>COUNTIFS(Processos!$X$10:$X$509,1,Processos!$Y$10:$Y$509,1),"",IF(INDEX(Processos!$H$10:$H$509,MATCH((ROW()-9+($J$8-1)*50),Processos!$AJ$10:$AJ$509,0))&" × "&INDEX(Processos!$I$10:$I$509,MATCH((ROW()-9+($J$8-1)*50),Processos!$AJ$10:$AJ$509,0))="","",INDEX(Processos!$H$10:$H$509,MATCH((ROW()-9+($J$8-1)*50),Processos!$AJ$10:$AJ$509,0))&" × "&INDEX(Processos!$I$10:$I$509,MATCH((ROW()-9+($J$8-1)*50),Processos!$AJ$10:$AJ$509,0)))),190)&" [...]",IF((ROW()-9+($J$8-1)*50)>COUNTIFS(Processos!$X$10:$X$509,1,Processos!$Y$10:$Y$509,1),"",IF(INDEX(Processos!$H$10:$H$509,MATCH((ROW()-9+($J$8-1)*50),Processos!$AJ$10:$AJ$509,0))&" × "&INDEX(Processos!$I$10:$I$509,MATCH((ROW()-9+($J$8-1)*50),Processos!$AJ$10:$AJ$509,0))="","",INDEX(Processos!$H$10:$H$509,MATCH((ROW()-9+($J$8-1)*50),Processos!$AJ$10:$AJ$509,0))&" × "&INDEX(Processos!$I$10:$I$509,MATCH((ROW()-9+($J$8-1)*50),Processos!$AJ$10:$AJ$509,0))))),CHAR(10)," "),CHAR(13)," ")) -> GUILHERME SANTOS MOREIRA × 1 - Consórcio Spavias - Alta Spavias Engenharia LTDA 2 - Alta Engenharia 3 - Cava Engenharia | D12: =SUBSTITUTE(SUBSTITUTE(IF(LEN(IF((ROW()-9+($J$8-1)*50)>COUNTIFS(Processos!$X$10:$X$509,1,Processos!$Y$10:$Y$509,1),"",IF(INDEX(Processos!$M$10:$M$509,MATCH((ROW()-9+($J$8-1)*50),Processos!$AJ$10:$AJ$509,0))="","",INDEX(Processos!$M$10:$M$509,MATCH((ROW()-9+($J$8-1)*50),Processos!$AJ$10:$AJ$509,0)))))>190,LEFT(IF((ROW()-9+($J$8-1)*50)>COUNTIFS(Processos!$X$10:$X$509,1,Processos!$Y$10:$Y$509,1),"",IF(INDEX(Processos!$M$10:$M$509,MATCH((ROW()-9+($J$8-1)*50),Processos!$AJ$10:$AJ$509,0))="","",INDEX(Processos!$M$10:$M$509,MATCH((ROW()-9+($J$8-1)*50),Processos!$AJ$10:$AJ$509,0)))),190)&" [...]",IF((ROW()-9+($J$8-1)*50)>COUNTIFS(Processos!$X$10:$X$509,1,Processos!$Y$10:$Y$509,1),"",IF(INDEX(Processos!$M$10:$M$509,MATCH((ROW()-9+($J$8-1)*50),Processos!$AJ$10:$AJ$509,0))="","",INDEX(Processos!$M$10:$M$509,MATCH((ROW()-9+($J$8-1)*50),Processos!$AJ$10:$AJ$509,0))))),CHAR(10)," "),CHAR(13)," ") -> O trabalhador pede execução provisória da sentença porque a empresa não cumpriu acordo trabalhista de R$ 50.000. Após decisões favoráveis na Justiça e vários recursos das empresas, ele reque [...] | E12: =IF($A12="","",IFERROR(INDEX(Processos!$AR$10:$AR$509,MATCH($A12,Processos!$A$10:$A$509,0)),"")&CHAR(10)&IFERROR(IF(OR(INDEX(Origem!$AB$10:$AB$509,MATCH($A12,Origem!$A$10:$A$509,0))="",INDEX(Origem!$AB$10:$AB$509,MATCH($A12,Origem!$A$10:$A$509,0))="—"),"Origem: sem classificação","Origem: "&INDEX(Origem!$AB$10:$AB$509,MATCH($A12,Origem!$A$10:$A$509,0))&IF(INDEX(Origem!$AC$10:$AC$509,MATCH($A12,Origem!$A$10:$A$509,0))=""," (sem pontuação)"," • "&INDEX(Origem!$AC$10:$AC$509,MATCH($A12,Origem!$A$10:$A$509,0))&" pontos")),"Origem: sem classificação")) -> Prioridade crítica. Criticidade herdada da planilha de origem; validar. Não confirma bloqueio/penhora vigente. Origem: 🔴 CRÍTICO • 70 pontos | F12: =IF((ROW()-9+($J$8-1)*50)>COUNTIFS(Processos!$X$10:$X$509,1,Processos!$Y$10:$Y$509,1),"",IF(INDEX(Processos!$AQ$10:$AQ$509,MATCH((ROW()-9+($J$8-1)*50),Processos!$AJ$10:$AJ$509,0))="","",INDEX(Processos!$AQ$10:$AQ$509,MATCH((ROW()-9+($J$8-1)*50),Processos!$AJ$10:$AJ$509,0)))) -> 58038.42 | G12: =IF((ROW()-9+($J$8-1)*50)>COUNTIFS(Processos!$X$10:$X$509,1,Processos!$Y$10:$Y$509,1),"",IFERROR(HYPERLINK("#'Ficha'!C6","Selecionar na Ficha"),"Selecionar na Ficha")) -> Selecionar na Ficha
A13: =IF((ROW()-9+($J$8-1)*50)>COUNTIFS(Processos!$X$10:$X$509,1,Processos!$Y$10:$Y$509,1),"",IF(INDEX(Processos!$A$10:$A$509,MATCH((ROW()-9+($J$8-1)*50),Processos!$AJ$10:$AJ$509,0))="","",INDEX(Processos!$A$10:$A$509,MATCH((ROW()-9+($J$8-1)*50),Processos!$AJ$10:$AJ$509,0)))) -> 0001532-68.2015.5.10.0005 | B13: =IF((ROW()-9+($J$8-1)*50)>COUNTIFS(Processos!$X$10:$X$509,1,Processos!$Y$10:$Y$509,1),"",IF(INDEX(Processos!$D$10:$D$509,MATCH((ROW()-9+($J$8-1)*50),Processos!$AJ$10:$AJ$509,0))="","",INDEX(Processos!$D$10:$D$509,MATCH((ROW()-9+($J$8-1)*50),Processos!$AJ$10:$AJ$509,0)))) -> BMM Advogados | C13: =IF(LEN(SUBSTITUTE(SUBSTITUTE(IF(LEN(IF((ROW()-9+($J$8-1)*50)>COUNTIFS(Processos!$X$10:$X$509,1,Processos!$Y$10:$Y$509,1),"",IF(INDEX(Processos!$H$10:$H$509,MATCH((ROW()-9+($J$8-1)*50),Processos!$AJ$10:$AJ$509,0))&" × "&INDEX(Processos!$I$10:$I$509,MATCH((ROW()-9+($J$8-1)*50),Processos!$AJ$10:$AJ$509,0))="","",INDEX(Processos!$H$10:$H$509,MATCH((ROW()-9+($J$8-1)*50),Processos!$AJ$10:$AJ$509,0))&" × "&INDEX(Processos!$I$10:$I$509,MATCH((ROW()-9+($J$8-1)*50),Processos!$AJ$10:$AJ$509,0)))))>190,LEFT(IF((ROW()-9+($J$8-1)*50)>COUNTIFS(Processos!$X$10:$X$509,1,Processos!$Y$10:$Y$509,1),"",IF(INDEX(Processos!$H$10:$H$509,MATCH((ROW()-9+($J$8-1)*50),Processos!$AJ$10:$AJ$509,0))&" × "&INDEX(Processos!$I$10:$I$509,MATCH((ROW()-9+($J$8-1)*50),Processos!$AJ$10:$AJ$509,0))="","",INDEX(Processos!$H$10:$H$509,MATCH((ROW()-9+($J$8-1)*50),Processos!$AJ$10:$AJ$509,0))&" × "&INDEX(Processos!$I$10:$I$509,MATCH((ROW()-9+($J$8-1)*50),Processos!$AJ$10:$AJ$509,0)))),190)&" [...]",IF((ROW()-9+($J$8-1)*50)>COUNTIFS(Processos!$X$10:$X$509,1,Processos!$Y$10:$Y$509,1),"",IF(INDEX(Processos!$H$10:$H$509,MATCH((ROW()-9+($J$8-1)*50),Processos!$AJ$10:$AJ$509,0))&" × "&INDEX(Processos!$I$10:$I$509,MATCH((ROW()-9+($J$8-1)*50),Processos!$AJ$10:$AJ$509,0))="","",INDEX(Processos!$H$10:$H$509,MATCH((ROW()-9+($J$8-1)*50),Processos!$AJ$10:$AJ$509,0))&" × "&INDEX(Processos!$I$10:$I$509,MATCH((ROW()-9+($J$8-1)*50),Processos!$AJ$10:$AJ$509,0))))),CHAR(10)," "),CHAR(13)," "))>150,LEFT(SUBSTITUTE(SUBSTITUTE(IF(LEN(IF((ROW()-9+($J$8-1)*50)>COUNTIFS(Processos!$X$10:$X$509,1,Processos!$Y$10:$Y$509,1),"",IF(INDEX(Processos!$H$10:$H$509,MATCH((ROW()-9+($J$8-1)*50),Processos!$AJ$10:$AJ$509,0))&" × "&INDEX(Processos!$I$10:$I$509,MATCH((ROW()-9+($J$8-1)*50),Processos!$AJ$10:$AJ$509,0))="","",INDEX(Processos!$H$10:$H$509,MATCH((ROW()-9+($J$8-1)*50),Processos!$AJ$10:$AJ$509,0))&" × "&INDEX(Processos!$I$10:$I$509,MATCH((ROW()-9+($J$8-1)*50),Processos!$AJ$10:$AJ$509,0)))))>190,LEFT(IF((ROW()-9+($J$8-1)*50)>COUNTIFS(Processos!$X$10:$X$509,1,Processos!$Y$10:$Y$509,1),"",IF(INDEX(Processos!$H$10:$H$509,MATCH((ROW()-9+($J$8-1)*50),Processos!$AJ$10:$AJ$509,0))&" × "&INDEX(Processos!$I$10:$I$509,MATCH((ROW()-9+($J$8-1)*50),Processos!$AJ$10:$AJ$509,0))="","",INDEX(Processos!$H$10:$H$509,MATCH((ROW()-9+($J$8-1)*50),Processos!$AJ$10:$AJ$509,0))&" × "&INDEX(Processos!$I$10:$I$509,MATCH((ROW()-9+($J$8-1)*50),Processos!$AJ$10:$AJ$509,0)))),190)&" [...]",IF((ROW()-9+($J$8-1)*50)>COUNTIFS(Processos!$X$10:$X$509,1,Processos!$Y$10:$Y$509,1),"",IF(INDEX(Processos!$H$10:$H$509,MATCH((ROW()-9+($J$8-1)*50),Processos!$AJ$10:$AJ$509,0))&" × "&INDEX(Processos!$I$10:$I$509,MATCH((ROW()-9+($J$8-1)*50),Processos!$AJ$10:$AJ$509,0))="","",INDEX(Processos!$H$10:$H$509,MATCH((ROW()-9+($J$8-1)*50),Processos!$AJ$10:$AJ$509,0))&" × "&INDEX(Processos!$I$10:$I$509,MATCH((ROW()-9+($J$8-1)*50),Processos!$AJ$10:$AJ$509,0))))),CHAR(10)," "),CHAR(13)," "),150)&" [...]",SUBSTITUTE(SUBSTITUTE(IF(LEN(IF((ROW()-9+($J$8-1)*50)>COUNTIFS(Processos!$X$10:$X$509,1,Processos!$Y$10:$Y$509,1),"",IF(INDEX(Processos!$H$10:$H$509,MATCH((ROW()-9+($J$8-1)*50),Processos!$AJ$10:$AJ$509,0))&" × "&INDEX(Processos!$I$10:$I$509,MATCH((ROW()-9+($J$8-1)*50),Processos!$AJ$10:$AJ$509,0))="","",INDEX(Processos!$H$10:$H$509,MATCH((ROW()-9+($J$8-1)*50),Processos!$AJ$10:$AJ$509,0))&" × "&INDEX(Processos!$I$10:$I$509,MATCH((ROW()-9+($J$8-1)*50),Processos!$AJ$10:$AJ$509,0)))))>190,LEFT(IF((ROW()-9+($J$8-1)*50)>COUNTIFS(Processos!$X$10:$X$509,1,Processos!$Y$10:$Y$509,1),"",IF(INDEX(Processos!$H$10:$H$509,MATCH((ROW()-9+($J$8-1)*50),Processos!$AJ$10:$AJ$509,0))&" × "&INDEX(Processos!$I$10:$I$509,MATCH((ROW()-9+($J$8-1)*50),Processos!$AJ$10:$AJ$509,0))="","",INDEX(Processos!$H$10:$H$509,MATCH((ROW()-9+($J$8-1)*50),Processos!$AJ$10:$AJ$509,0))&" × "&INDEX(Processos!$I$10:$I$509,MATCH((ROW()-9+($J$8-1)*50),Processos!$AJ$10:$AJ$509,0)))),190)&" [...]",IF((ROW()-9+($J$8-1)*50)>COUNTIFS(Processos!$X$10:$X$509,1,Processos!$Y$10:$Y$509,1),"",IF(INDEX(Processos!$H$10:$H$509,MATCH((ROW()-9+($J$8-1)*50),Processos!$AJ$10:$AJ$509,0))&" × "&INDEX(Processos!$I$10:$I$509,MATCH((ROW()-9+($J$8-1)*50),Processos!$AJ$10:$AJ$509,0))="","",INDEX(Processos!$H$10:$H$509,MATCH((ROW()-9+($J$8-1)*50),Processos!$AJ$10:$AJ$509,0))&" × "&INDEX(Processos!$I$10:$I$509,MATCH((ROW()-9+($J$8-1)*50),Processos!$AJ$10:$AJ$509,0))))),CHAR(10)," "),CHAR(13)," ")) -> 1 - MARIA TERESA SOARES MOREIRA 2 - JOSÉ FONSECA FILHO × 1 - Cesar Transportes, Guindastes e Equipamentos LTDA 2 - União - Ministérios dos Transportes [...] | D13: =SUBSTITUTE(SUBSTITUTE(IF(LEN(IF((ROW()-9+($J$8-1)*50)>COUNTIFS(Processos!$X$10:$X$509,1,Processos!$Y$10:$Y$509,1),"",IF(INDEX(Processos!$M$10:$M$509,MATCH((ROW()-9+($J$8-1)*50),Processos!$AJ$10:$AJ$509,0))="","",INDEX(Processos!$M$10:$M$509,MATCH((ROW()-9+($J$8-1)*50),Processos!$AJ$10:$AJ$509,0)))))>190,LEFT(IF((ROW()-9+($J$8-1)*50)>COUNTIFS(Processos!$X$10:$X$509,1,Processos!$Y$10:$Y$509,1),"",IF(INDEX(Processos!$M$10:$M$509,MATCH((ROW()-9+($J$8-1)*50),Processos!$AJ$10:$AJ$509,0))="","",INDEX(Processos!$M$10:$M$509,MATCH((ROW()-9+($J$8-1)*50),Processos!$AJ$10:$AJ$509,0)))),190)&" [...]",IF((ROW()-9+($J$8-1)*50)>COUNTIFS(Processos!$X$10:$X$509,1,Processos!$Y$10:$Y$509,1),"",IF(INDEX(Processos!$M$10:$M$509,MATCH((ROW()-9+($J$8-1)*50),Processos!$AJ$10:$AJ$509,0))="","",INDEX(Processos!$M$10:$M$509,MATCH((ROW()-9+($J$8-1)*50),Processos!$AJ$10:$AJ$509,0))))),CHAR(10)," "),CHAR(13)," ") -> Ação trabalhista de indenização proposta pelos pais de um trabalhador falecido (Juscelino Soares Fonseca) após acidente de trabalho em obra ferroviária. Eles alegam que o empregado morreu ao [...] | E13: =IF($A13="","",IFERROR(INDEX(Processos!$AR$10:$AR$509,MATCH($A13,Processos!$A$10:$A$509,0)),"")&CHAR(10)&IFERROR(IF(OR(INDEX(Origem!$AB$10:$AB$509,MATCH($A13,Origem!$A$10:$A$509,0))="",INDEX(Origem!$AB$10:$AB$509,MATCH($A13,Origem!$A$10:$A$509,0))="—"),"Origem: sem classificação","Origem: "&INDEX(Origem!$AB$10:$AB$509,MATCH($A13,Origem!$A$10:$A$509,0))&IF(INDEX(Origem!$AC$10:$AC$509,MATCH($A13,Origem!$A$10:$A$509,0))=""," (sem pontuação)"," • "&INDEX(Origem!$AC$10:$AC$509,MATCH($A13,Origem!$A$10:$A$509,0))&" pontos")),"Origem: sem classificação")) -> Prioridade crítica. Criticidade herdada da planilha de origem; validar. Não confirma bloqueio/penhora vigente. Origem: 🔴 CRÍTICO • 70 pontos | F13: =IF((ROW()-9+($J$8-1)*50)>COUNTIFS(Processos!$X$10:$X$509,1,Processos!$Y$10:$Y$509,1),"",IF(INDEX(Processos!$AQ$10:$AQ$509,MATCH((ROW()-9+($J$8-1)*50),Processos!$AJ$10:$AJ$509,0))="","",INDEX(Processos!$AQ$10:$AQ$509,MATCH((ROW()-9+($J$8-1)*50),Processos!$AJ$10:$AJ$509,0)))) -> 3000000 | G13: =IF((ROW()-9+($J$8-1)*50)>COUNTIFS(Processos!$X$10:$X$509,1,Processos!$Y$10:$Y$509,1),"",IFERROR(HYPERLINK("#'Ficha'!C6","Selecionar na Ficha"),"Selecionar na Ficha")) -> Selecionar na Ficha
A14: =IF((ROW()-9+($J$8-1)*50)>COUNTIFS(Processos!$X$10:$X$509,1,Processos!$Y$10:$Y$509,1),"",IF(INDEX(Processos!$A$10:$A$509,MATCH((ROW()-9+($J$8-1)*50),Processos!$AJ$10:$AJ$509,0))="","",INDEX(Processos!$A$10:$A$509,MATCH((ROW()-9+($J$8-1)*50),Processos!$AJ$10:$AJ$509,0)))) -> 0010993-94.2019.5.18.0104 | B14: =IF((ROW()-9+($J$8-1)*50)>COUNTIFS(Processos!$X$10:$X$509,1,Processos!$Y$10:$Y$509,1),"",IF(INDEX(Processos!$D$10:$D$509,MATCH((ROW()-9+($J$8-1)*50),Processos!$AJ$10:$AJ$509,0))="","",INDEX(Processos!$D$10:$D$509,MATCH((ROW()-9+($J$8-1)*50),Processos!$AJ$10:$AJ$509,0)))) -> BMM Advogados | C14: =IF(LEN(SUBSTITUTE(SUBSTITUTE(IF(LEN(IF((ROW()-9+($J$8-1)*50)>COUNTIFS(Processos!$X$10:$X$509,1,Processos!$Y$10:$Y$509,1),"",IF(INDEX(Processos!$H$10:$H$509,MATCH((ROW()-9+($J$8-1)*50),Processos!$AJ$10:$AJ$509,0))&" × "&INDEX(Processos!$I$10:$I$509,MATCH((ROW()-9+($J$8-1)*50),Processos!$AJ$10:$AJ$509,0))="","",INDEX(Processos!$H$10:$H$509,MATCH((ROW()-9+($J$8-1)*50),Processos!$AJ$10:$AJ$509,0))&" × "&INDEX(Processos!$I$10:$I$509,MATCH((ROW()-9+($J$8-1)*50),Processos!$AJ$10:$AJ$509,0)))))>190,LEFT(IF((ROW()-9+($J$8-1)*50)>COUNTIFS(Processos!$X$10:$X$509,1,Processos!$Y$10:$Y$509,1),"",IF(INDEX(Processos!$H$10:$H$509,MATCH((ROW()-9+($J$8-1)*50),Processos!$AJ$10:$AJ$509,0))&" × "&INDEX(Processos!$I$10:$I$509,MATCH((ROW()-9+($J$8-1)*50),Processos!$AJ$10:$AJ$509,0))="","",INDEX(Processos!$H$10:$H$509,MATCH((ROW()-9+($J$8-1)*50),Processos!$AJ$10:$AJ$509,0))&" × "&INDEX(Processos!$I$10:$I$509,MATCH((ROW()-9+($J$8-1)*50),Processos!$AJ$10:$AJ$509,0)))),190)&" [...]",IF((ROW()-9+($J$8-1)*50)>COUNTIFS(Processos!$X$10:$X$509,1,Processos!$Y$10:$Y$509,1),"",IF(INDEX(Processos!$H$10:$H$509,MATCH((ROW()-9+($J$8-1)*50),Processos!$AJ$10:$AJ$509,0))&" × "&INDEX(Processos!$I$10:$I$509,MATCH((ROW()-9+($J$8-1)*50),Processos!$AJ$10:$AJ$509,0))="","",INDEX(Processos!$H$10:$H$509,MATCH((ROW()-9+($J$8-1)*50),Processos!$AJ$10:$AJ$509,0))&" × "&INDEX(Processos!$I$10:$I$509,MATCH((ROW()-9+($J$8-1)*50),Processos!$AJ$10:$AJ$509,0))))),CHAR(10)," "),CHAR(13)," "))>150,LEFT(SUBSTITUTE(SUBSTITUTE(IF(LEN(IF((ROW()-9+($J$8-1)*50)>COUNTIFS(Processos!$X$10:$X$509,1,Processos!$Y$10:$Y$509,1),"",IF(INDEX(Processos!$H$10:$H$509,MATCH((ROW()-9+($J$8-1)*50),Processos!$AJ$10:$AJ$509,0))&" × "&INDEX(Processos!$I$10:$I$509,MATCH((ROW()-9+($J$8-1)*50),Processos!$AJ$10:$AJ$509,0))="","",INDEX(Processos!$H$10:$H$509,MATCH((ROW()-9+($J$8-1)*50),Processos!$AJ$10:$AJ$509,0))&" × "&INDEX(Processos!$I$10:$I$509,MATCH((ROW()-9+($J$8-1)*50),Processos!$AJ$10:$AJ$509,0)))))>190,LEFT(IF((ROW()-9+($J$8-1)*50)>COUNTIFS(Processos!$X$10:$X$509,1,Processos!$Y$10:$Y$509,1),"",IF(INDEX(Processos!$H$10:$H$509,MATCH((ROW()-9+($J$8-1)*50),Processos!$AJ$10:$AJ$509,0))&" × "&INDEX(Processos!$I$10:$I$509,MATCH((ROW()-9+($J$8-1)*50),Processos!$AJ$10:$AJ$509,0))="","",INDEX(Processos!$H$10:$H$509,MATCH((ROW()-9+($J$8-1)*50),Processos!$AJ$10:$AJ$509,0))&" × "&INDEX(Processos!$I$10:$I$509,MATCH((ROW()-9+($J$8-1)*50),Processos!$AJ$10:$AJ$509,0)))),190)&" [...]",IF((ROW()-9+($J$8-1)*50)>COUNTIFS(Processos!$X$10:$X$509,1,Processos!$Y$10:$Y$509,1),"",IF(INDEX(Processos!$H$10:$H$509,MATCH((ROW()-9+($J$8-1)*50),Processos!$AJ$10:$AJ$509,0))&" × "&INDEX(Processos!$I$10:$I$509,MATCH((ROW()-9+($J$8-1)*50),Processos!$AJ$10:$AJ$509,0))="","",INDEX(Processos!$H$10:$H$509,MATCH((ROW()-9+($J$8-1)*50),Processos!$AJ$10:$AJ$509,0))&" × "&INDEX(Processos!$I$10:$I$509,MATCH((ROW()-9+($J$8-1)*50),Processos!$AJ$10:$AJ$509,0))))),CHAR(10)," "),CHAR(13)," "),150)&" [...]",SUBSTITUTE(SUBSTITUTE(IF(LEN(IF((ROW()-9+($J$8-1)*50)>COUNTIFS(Processos!$X$10:$X$509,1,Processos!$Y$10:$Y$509,1),"",IF(INDEX(Processos!$H$10:$H$509,MATCH((ROW()-9+($J$8-1)*50),Processos!$AJ$10:$AJ$509,0))&" × "&INDEX(Processos!$I$10:$I$509,MATCH((ROW()-9+($J$8-1)*50),Processos!$AJ$10:$AJ$509,0))="","",INDEX(Processos!$H$10:$H$509,MATCH((ROW()-9+($J$8-1)*50),Processos!$AJ$10:$AJ$509,0))&" × "&INDEX(Processos!$I$10:$I$509,MATCH((ROW()-9+($J$8-1)*50),Processos!$AJ$10:$AJ$509,0)))))>190,LEFT(IF((ROW()-9+($J$8-1)*50)>COUNTIFS(Processos!$X$10:$X$509,1,Processos!$Y$10:$Y$509,1),"",IF(INDEX(Processos!$H$10:$H$509,MATCH((ROW()-9+($J$8-1)*50),Processos!$AJ$10:$AJ$509,0))&" × "&INDEX(Processos!$I$10:$I$509,MATCH((ROW()-9+($J$8-1)*50),Processos!$AJ$10:$AJ$509,0))="","",INDEX(Processos!$H$10:$H$509,MATCH((ROW()-9+($J$8-1)*50),Processos!$AJ$10:$AJ$509,0))&" × "&INDEX(Processos!$I$10:$I$509,MATCH((ROW()-9+($J$8-1)*50),Processos!$AJ$10:$AJ$509,0)))),190)&" [...]",IF((ROW()-9+($J$8-1)*50)>COUNTIFS(Processos!$X$10:$X$509,1,Processos!$Y$10:$Y$509,1),"",IF(INDEX(Processos!$H$10:$H$509,MATCH((ROW()-9+($J$8-1)*50),Processos!$AJ$10:$AJ$509,0))&" × "&INDEX(Processos!$I$10:$I$509,MATCH((ROW()-9+($J$8-1)*50),Processos!$AJ$10:$AJ$509,0))="","",INDEX(Processos!$H$10:$H$509,MATCH((ROW()-9+($J$8-1)*50),Processos!$AJ$10:$AJ$509,0))&" × "&INDEX(Processos!$I$10:$I$509,MATCH((ROW()-9+($J$8-1)*50),Processos!$AJ$10:$AJ$509,0))))),CHAR(10)," "),CHAR(13)," ")) -> Sindicato Dos Trabalhadores Nas Industrias Da Construcao × 1 - Consórcio Integral Spavias Trail Alta 2 - SPA Engenharia Indústria e Comércio LTDA 3 - [...] | D14: =SUBSTITUTE(SUBSTITUTE(IF(LEN(IF((ROW()-9+($J$8-1)*50)>COUNTIFS(Processos!$X$10:$X$509,1,Processos!$Y$10:$Y$509,1),"",IF(INDEX(Processos!$M$10:$M$509,MATCH((ROW()-9+($J$8-1)*50),Processos!$AJ$10:$AJ$509,0))="","",INDEX(Processos!$M$10:$M$509,MATCH((ROW()-9+($J$8-1)*50),Processos!$AJ$10:$AJ$509,0)))))>190,LEFT(IF((ROW()-9+($J$8-1)*50)>COUNTIFS(Processos!$X$10:$X$509,1,Processos!$Y$10:$Y$509,1),"",IF(INDEX(Processos!$M$10:$M$509,MATCH((ROW()-9+($J$8-1)*50),Processos!$AJ$10:$AJ$509,0))="","",INDEX(Processos!$M$10:$M$509,MATCH((ROW()-9+($J$8-1)*50),Processos!$AJ$10:$AJ$509,0)))),190)&" [...]",IF((ROW()-9+($J$8-1)*50)>COUNTIFS(Processos!$X$10:$X$509,1,Processos!$Y$10:$Y$509,1),"",IF(INDEX(Processos!$M$10:$M$509,MATCH((ROW()-9+($J$8-1)*50),Processos!$AJ$10:$AJ$509,0))="","",INDEX(Processos!$M$10:$M$509,MATCH((ROW()-9+($J$8-1)*50),Processos!$AJ$10:$AJ$509,0))))),CHAR(10)," "),CHAR(13)," ") -> O recurso do Sindicato foi provido para condenar a Alta até o período que ela particilou do processo, porém, em sustenação oral feita pelo BMM, o Relator pediu vista do processo. Estamos agu [...] | E14: =IF($A14="","",IFERROR(INDEX(Processos!$AR$10:$AR$509,MATCH($A14,Processos!$A$10:$A$509,0)),"")&CHAR(10)&IFERROR(IF(OR(INDEX(Origem!$AB$10:$AB$509,MATCH($A14,Origem!$A$10:$A$509,0))="",INDEX(Origem!$AB$10:$AB$509,MATCH($A14,Origem!$A$10:$A$509,0))="—"),"Origem: sem classificação","Origem: "&INDEX(Origem!$AB$10:$AB$509,MATCH($A14,Origem!$A$10:$A$509,0))&IF(INDEX(Origem!$AC$10:$AC$509,MATCH($A14,Origem!$A$10:$A$509,0))=""," (sem pontuação)"," • "&INDEX(Origem!$AC$10:$AC$509,MATCH($A14,Origem!$A$10:$A$509,0))&" pontos")),"Origem: sem classificação")) -> Prioridade crítica. Criticidade herdada da planilha de origem; validar. Não confirma bloqueio/penhora vigente. Origem: 🔴 CRÍTICO • 65 pontos | F14: =IF((ROW()-9+($J$8-1)*50)>COUNTIFS(Processos!$X$10:$X$509,1,Processos!$Y$10:$Y$509,1),"",IF(INDEX(Processos!$AQ$10:$AQ$509,MATCH((ROW()-9+($J$8-1)*50),Processos!$AJ$10:$AJ$509,0))="","",INDEX(Processos!$AQ$10:$AQ$509,MATCH((ROW()-9+($J$8-1)*50),Processos!$AJ$10:$AJ$509,0)))) -> 2018074.8 | G14: =IF((ROW()-9+($J$8-1)*50)>COUNTIFS(Processos!$X$10:$X$509,1,Processos!$Y$10:$Y$509,1),"",IFERROR(HYPERLINK("#'Ficha'!C6","Selecionar na Ficha"),"Selecionar na Ficha")) -> Selecionar na Ficha
